<?xml version="1.0" encoding="utf-8"?>
<!-- =================================================================================== -->
<!-- |    This document was autogenerated by xacro from /is/ei/sjoshi/challenge_space/blmc_ei/workspace/src/catkin/robots/robot_properties/robot_properties_fingers/xacro/pro/fingerpro.urdf.xacro | -->
<!-- |    EDITING THIS FILE BY HAND IS NOT RECOMMENDED                                 | -->
<!-- =================================================================================== -->
<robot name="fingerpro">
  <!--
    Frames are defined such that they all align with the base frame when all
    joints are at position zero.

    In zero-configuration the origins of all joints are in one line.

    In zero-configuration the origin of the base link is exactly above the
    finger tip which should make it easy to place the finger in the world.
    -->
  <!--
    Frames are defined such that they all align with the base frame when all
    joints are at position zero.

    In zero-configuration the origins of all joints are in one line.

    In zero-configuration the origin of the base link is exactly above the
    finger tip which should make it easy to place the finger in the world.
    -->
  <material name="finger_material">
    <color rgba="0.6 0.6 0.6 1.0"/>
  </material>
  <!--
        Fixed links for the finger base (parts where the upper link is mounted).
        Note: Link Frames already coincide with the joint location
        -->
  <link name="finger_base_link">
    <visual>
      <origin rpy="0 0 0" xyz="0 0.23295 0"/>
      <geometry>
        <mesh filename="package://robot_properties_fingers/meshes/stl/pro/SIM__BL-Finger_Base.stl" scale="1.0 1.0 1.0"/>
      </geometry>
      <material name="finger_material"/>
    </visual>
    <collision>
      <origin rpy="0 0 0" xyz="0 0.23295 0"/>
      <geometry>
        <mesh filename="package://robot_properties_fingers/meshes/stl/pro/SIM__BL-Finger_Base.stl" scale="1.0 1.0 1.0"/>
      </geometry>
    </collision>
    <inertial>
      <origin rpy="0 0 0" xyz="0 0 0"/>
      <mass value="1"/>
      <inertia ixx="0.000416666666667" ixy="0" ixz="0" iyy="0.000416666666667" iyz="0" izz="0.000416666666667"/>
    </inertial>
  </link>
  <link name="finger_upper_link">
    <visual>
      <origin rpy="0 0 0" xyz="0 0.0235 0"/>
      <geometry>
        <mesh filename="package://robot_properties_fingers/meshes/stl/pro/SIM__BL-Finger_Proximal.stl" scale="1.0 1.0 1.0"/>
      </geometry>
      <material name="finger_material"/>
    </visual>
    <collision>
      <origin rpy="0 0 0" xyz="0 0.0235 0"/>
      <geometry>
        <mesh filename="package://robot_properties_fingers/meshes/stl/pro/SIM__BL-Finger_Proximal.stl" scale="1.0 1.0 1.0"/>
      </geometry>
    </collision>
    <inertial>
      <origin rpy="0 0 0" xyz="0 0.06 0"/>
      <mass value="0.26"/>
      <inertia ixx="0.000459333333333" ixy="0" ixz="0" iyy="6.93333333333e-05" iyz="0" izz="0.000459333333333"/>
    </inertial>
  </link>
  <link name="finger_middle_link">
    <visual>
      <origin rpy="1.57079632679 0 0" xyz="0 0 0"/>
      <geometry>
        <mesh filename="package://robot_properties_fingers/meshes/stl/pro/SIM__BL-Finger_Intermediate.stl" scale="1.0 1.0 1.0"/>
      </geometry>
      <material name="finger_material"/>
    </visual>
    <collision>
      <origin rpy="1.57079632679 0 0" xyz="0 0 0"/>
      <geometry>
        <mesh filename="package://robot_properties_fingers/meshes/stl/pro/SIM__BL-Finger_Intermediate.stl" scale="1.0 1.0 1.0"/>
      </geometry>
    </collision>
    <inertial>
      <origin rpy="0 0 0" xyz="0.028 0 -0.08"/>
      <mass value="0.25"/>
      <inertia ixx="0.000441666666667" ixy="0" ixz="0" iyy="0.000441666666667" iyz="0" izz="6.66666666667e-05"/>
    </inertial>
  </link>
  <link name="finger_lower_link">
    <visual>
      <origin rpy="1.57079632679 0 0" xyz="0 0 0"/>
      <geometry>
        <mesh filename="package://robot_properties_fingers/meshes/stl/pro/SIM__BL-Finger_Tip_without_tip.stl" scale="1.0 1.0 1.0"/>
      </geometry>
      <material name="finger_material"/>
    </visual>
    <collision>
      <origin rpy="1.57079632679 0 0" xyz="0 0 0"/>
      <geometry>
        <mesh filename="package://robot_properties_fingers/meshes/stl/pro/SIM__BL-Finger_Tip_without_tip.stl" scale="1.0 1.0 1.0"/>
      </geometry>
    </collision>
    <inertial>
      <origin rpy="0 0 0" xyz="0 0 -0.06"/>
      <mass value="0.021"/>
      <inertia ixx="3.5e-05" ixy="0" ixz="0" iyy="3.5e-05" iyz="0" izz="1.4e-06"/>
    </inertial>
  </link>
  <!-- fixed link for finger tip -->
  <link name="finger_tip_link">
    <visual>
      <origin rpy="1.57079632679 0 0" xyz="-0.0185 0 0.1626"/>
      <geometry>
        <mesh filename="package://robot_properties_fingers/meshes/stl/pro/SIM__BL-Finger_Tip_actual_tip.stl" scale="1.0 1.0 1.0"/>
      </geometry>
      <material name="finger_material"/>
    </visual>
    <collision>
      <origin rpy="1.57079632679 0 0" xyz="-0.0185 0 0.1626"/>
      <geometry>
        <mesh filename="package://robot_properties_fingers/meshes/stl/pro/SIM__BL-Finger_Tip_actual_tip.stl" scale="1.0 1.0 1.0"/>
      </geometry>
    </collision>
    <inertial>
      <origin rpy="0 0 0" xyz="0 0 0"/>
      <mass value="0.031"/>
      <inertia ixx="5.16666666667e-07" ixy="0" ixz="0" iyy="5.16666666667e-07" iyz="0" izz="5.16666666667e-07"/>
    </inertial>
  </link>
  <joint name="finger_lower_to_tip_joint" type="fixed">
    <parent link="finger_lower_link"/>
    <child link="finger_tip_link"/>
    <origin xyz="0.0185 0 -0.1626"/>
  </joint>
  <!-- kinematics -->
  <!-- NOTE: Joint limits are set according to soft limits in the
             configuration of the real robot (i.e. not according to physical
             limits). -->
  <joint name="finger_base_to_upper_joint" type="revolute">
    <parent link="finger_base_link"/>
    <child link="finger_upper_link"/>
    <limit effort="1000" lower="-0.9" upper="1.4" velocity="1000"/>
    <axis xyz="0 1 0"/>
    <origin rpy="0 0 0" xyz="0 0 0"/>
  </joint>
  <joint name="finger_upper_to_middle_joint" type="revolute">
    <parent link="finger_upper_link"/>
    <child link="finger_middle_link"/>
    <limit effort="1000" lower="-1.57" upper="1.57" velocity="1000"/>
    <axis xyz="1 0 0"/>
    <origin rpy="0 0 0" xyz="0.01685 0.0505 0"/>
  </joint>
  <joint name="finger_middle_to_lower_joint" type="revolute">
    <parent link="finger_middle_link"/>
    <child link="finger_lower_link"/>
    <limit effort="1000" lower="-2.7" upper="0.0" velocity="1000"/>
    <axis xyz="1 0 0"/>
    <origin rpy="0 0 0" xyz="0.04922 0 -0.16"/>
  </joint>
  <!--
    Define the global base link and place the finger relative to it.
    Note: Here I've used the center point of the center piece as the origin 
    -->
  <link name="center_link">
    <visual>
      <origin rpy="0 0 0" xyz="0 0 0"/>
      <geometry>
        <mesh filename="package://robot_properties_fingers/meshes/stl/pro/SIM__BL-Finger_Center.stl" scale="1.0 1.0 1.0"/>
      </geometry>
      <material name="finger_material"/>
    </visual>
    <collision>
      <origin rpy="0 0 0" xyz="0 0 0"/>
      <geometry>
        <mesh filename="package://robot_properties_fingers/meshes/stl/pro/SIM__BL-Finger_Center.stl" scale="1.0 1.0 1.0"/>
      </geometry>
    </collision>
    <inertial>
      <origin rpy="0 0 0" xyz="0 0 0"/>
      <mass value="1"/>
      <inertia ixx="4.16666666667e-06" ixy="0" ixz="0" iyy="4.16666666667e-06" iyz="0" izz="4.16666666667e-06"/>
    </inertial>
  </link>
  <joint name="base_to_finger" type="fixed">
    <parent link="center_link"/>
    <child link="finger_base_link"/>
    <origin xyz="0 0 0"/>
  </joint>
</robot>
