<?xml version="1.0" encoding="utf-8"?>
<!-- =================================================================================== -->
<!-- |    This document was autogenerated by xacro from /is/ei/sjoshi/challenge_space/blmc_ei/workspace/src/catkin/robots/robot_properties/robot_properties_fingers/xacro/pro/trifingerpro_with_stage.urdf.xacro | -->
<!-- |    EDITING THIS FILE BY HAND IS NOT RECOMMENDED                                 | -->
<!-- =================================================================================== -->
<robot name="trifingerpro_with_stage">
  <!--
    Frames are defined such that they all align with the base frame when all
    joints are at position zero.

    In zero-configuration the origins of all joints are in one line.

    In zero-configuration the origin of the base link is exactly above the
    finger tip which should make it easy to place the finger in the world.
    -->
  <material name="finger_0_material">
    <color rgba="0.6 0.0 0.0 1.0"/>
  </material>
  <material name="finger_120_material">
    <color rgba="0.0 0.6 0.0 1.0"/>
  </material>
  <material name="finger_240_material">
    <color rgba="0.0 0.0 0.6 1.0"/>
  </material>
  <material name="real_finger_material">
    <color rgba="0.83 0.79 0.82 1.0"/>
  </material>
  <!-- Define the global base_link and place all other objects relative to it. -->
  <link name="base_link">
    <inertial>
      <origin rpy="0 0 0" xyz="0 0 0"/>
      <mass value="1"/>
      <inertia ixx="4.16666666667e-06" ixy="0" ixz="0" iyy="4.16666666667e-06" iyz="0" izz="4.16666666667e-06"/>
    </inertial>
  </link>
  <!-- Define the upper holder -->
  <link name="upper_holder_link">
    <visual>
      <origin rpy="0 0 0" xyz="0 0 0"/>
      <geometry>
        <mesh filename="package://robot_properties_fingers/meshes/stl/pro/SIM__BL-Finger_Center.stl" scale="1.0 1.0 1.0"/>
      </geometry>
      <material name="real_finger_material"/>
    </visual>
    <inertial>
      <origin rpy="0 0 0" xyz="0 0 0"/>
      <mass value="1"/>
      <inertia ixx="4.16666666667e-06" ixy="0" ixz="0" iyy="4.16666666667e-06" iyz="0" izz="4.16666666667e-06"/>
    </inertial>
  </link>
  <joint name="base_to_upper_holder_joint" type="fixed">
    <parent link="base_link"/>
    <child link="upper_holder_link"/>
    <origin xyz="0 0 0.29"/>
  </joint>
  <!--
        Fixed links for the finger base (parts where the upper link is mounted).
        Note: Link Frames already coincide with the joint location
        -->
  <link name="finger_base_link_0">
    <visual>
      <origin rpy="0 0 0" xyz="0 0.23295 0"/>
      <geometry>
        <mesh filename="package://robot_properties_fingers/meshes/stl/pro/SIM__BL-Finger_Base.stl" scale="1.0 1.0 1.0"/>
      </geometry>
      <material name="real_finger_material"/>
    </visual>
    <collision>
      <origin rpy="0 0 0" xyz="0 0.23295 0"/>
      <geometry>
        <mesh filename="package://robot_properties_fingers/meshes/stl/pro/SIM__BL-Finger_Base.stl" scale="1.0 1.0 1.0"/>
      </geometry>
    </collision>
    <inertial>
      <origin rpy="0 0 0" xyz="0 0 0"/>
      <mass value="1"/>
      <inertia ixx="0.000416666666667" ixy="0" ixz="0" iyy="0.000416666666667" iyz="0" izz="0.000416666666667"/>
    </inertial>
  </link>
  <link name="finger_upper_link_0">
    <visual>
      <origin rpy="0 0 0" xyz="0 0.0235 0"/>
      <geometry>
        <mesh filename="package://robot_properties_fingers/meshes/stl/pro/SIM__BL-Finger_Proximal.stl" scale="1.0 1.0 1.0"/>
      </geometry>
      <material name="real_finger_material"/>
    </visual>
    <collision>
      <origin rpy="0 0 0" xyz="0 0.0235 0"/>
      <geometry>
        <mesh filename="package://robot_properties_fingers/meshes/stl/pro/SIM__BL-Finger_Proximal.stl" scale="1.0 1.0 1.0"/>
      </geometry>
    </collision>
    <inertial>
      <origin rpy="0 0 0" xyz="0 0.06 0"/>
      <mass value="0.26"/>
      <inertia ixx="0.000459333333333" ixy="0" ixz="0" iyy="6.93333333333e-05" iyz="0" izz="0.000459333333333"/>
    </inertial>
  </link>
  <link name="finger_middle_link_0">
    <visual>
      <origin rpy="1.57079632679 0 0" xyz="0 0 0"/>
      <geometry>
        <mesh filename="package://robot_properties_fingers/meshes/stl/pro/SIM__BL-Finger_Intermediate.stl" scale="1.0 1.0 1.0"/>
      </geometry>
      <material name="real_finger_material"/>
    </visual>
    <collision>
      <origin rpy="1.57079632679 0 0" xyz="0 0 0"/>
      <geometry>
        <mesh filename="package://robot_properties_fingers/meshes/stl/pro/SIM__BL-Finger_Intermediate.stl" scale="1.0 1.0 1.0"/>
      </geometry>
    </collision>
    <inertial>
      <origin rpy="0 0 0" xyz="0.028 0 -0.08"/>
      <mass value="0.25"/>
      <inertia ixx="0.000441666666667" ixy="0" ixz="0" iyy="0.000441666666667" iyz="0" izz="6.66666666667e-05"/>
    </inertial>
  </link>
  <link name="finger_lower_link_0">
    <visual>
      <origin rpy="1.57079632679 0 0" xyz="0 0 0"/>
      <geometry>
        <mesh filename="package://robot_properties_fingers/meshes/stl/pro/SIM__BL-Finger_Tip_without_tip.stl" scale="1.0 1.0 1.0"/>
      </geometry>
      <material name="real_finger_material"/>
    </visual>
    <collision>
      <origin rpy="1.57079632679 0 0" xyz="0 0 0"/>
      <geometry>
        <mesh filename="package://robot_properties_fingers/meshes/stl/pro/SIM__BL-Finger_Tip_without_tip.stl" scale="1.0 1.0 1.0"/>
      </geometry>
    </collision>
    <inertial>
      <origin rpy="0 0 0" xyz="0 0 -0.06"/>
      <mass value="0.021"/>
      <inertia ixx="3.5e-05" ixy="0" ixz="0" iyy="3.5e-05" iyz="0" izz="1.4e-06"/>
    </inertial>
  </link>
  <!-- fixed link for finger tip -->
  <link name="finger_tip_link_0">
    <visual>
      <origin rpy="1.57079632679 0 0" xyz="-0.0185 0 0.1626"/>
      <geometry>
        <mesh filename="package://robot_properties_fingers/meshes/stl/pro/SIM__BL-Finger_Tip_actual_tip.stl" scale="1.0 1.0 1.0"/>
      </geometry>
      <material name="real_finger_material"/>
    </visual>
    <collision>
      <origin rpy="1.57079632679 0 0" xyz="-0.0185 0 0.1626"/>
      <geometry>
        <mesh filename="package://robot_properties_fingers/meshes/stl/pro/SIM__BL-Finger_Tip_actual_tip.stl" scale="1.0 1.0 1.0"/>
      </geometry>
    </collision>
    <inertial>
      <origin rpy="0 0 0" xyz="0 0 0"/>
      <mass value="0.031"/>
      <inertia ixx="5.16666666667e-07" ixy="0" ixz="0" iyy="5.16666666667e-07" iyz="0" izz="5.16666666667e-07"/>
    </inertial>
  </link>
  <joint name="finger_lower_to_tip_joint_0" type="fixed">
    <parent link="finger_lower_link_0"/>
    <child link="finger_tip_link_0"/>
    <origin xyz="0.0185 0 -0.1626"/>
  </joint>
  <!-- kinematics -->
  <!-- NOTE: Joint limits are set according to soft limits in the
             configuration of the real robot (i.e. not according to physical
             limits). -->
  <joint name="finger_base_to_upper_joint_0" type="revolute">
    <parent link="finger_base_link_0"/>
    <child link="finger_upper_link_0"/>
    <limit effort="1000" lower="-0.9" upper="1.4" velocity="1000"/>
    <axis xyz="0 1 0"/>
    <origin rpy="0 0 0" xyz="0 0 0"/>
  </joint>
  <joint name="finger_upper_to_middle_joint_0" type="revolute">
    <parent link="finger_upper_link_0"/>
    <child link="finger_middle_link_0"/>
    <limit effort="1000" lower="-1.57" upper="1.57" velocity="1000"/>
    <axis xyz="1 0 0"/>
    <origin rpy="0 0 0" xyz="0.01685 0.0505 0"/>
  </joint>
  <joint name="finger_middle_to_lower_joint_0" type="revolute">
    <parent link="finger_middle_link_0"/>
    <child link="finger_lower_link_0"/>
    <limit effort="1000" lower="-2.7" upper="0.0" velocity="1000"/>
    <axis xyz="1 0 0"/>
    <origin rpy="0 0 0" xyz="0.04922 0 -0.16"/>
  </joint>
  <!--
        Fixed links for the finger base (parts where the upper link is mounted).
        Note: Link Frames already coincide with the joint location
        -->
  <link name="finger_base_link_120">
    <visual>
      <origin rpy="0 0 0" xyz="0 0.23295 0"/>
      <geometry>
        <mesh filename="package://robot_properties_fingers/meshes/stl/pro/SIM__BL-Finger_Base.stl" scale="1.0 1.0 1.0"/>
      </geometry>
      <material name="real_finger_material"/>
    </visual>
    <collision>
      <origin rpy="0 0 0" xyz="0 0.23295 0"/>
      <geometry>
        <mesh filename="package://robot_properties_fingers/meshes/stl/pro/SIM__BL-Finger_Base.stl" scale="1.0 1.0 1.0"/>
      </geometry>
    </collision>
    <inertial>
      <origin rpy="0 0 0" xyz="0 0 0"/>
      <mass value="1"/>
      <inertia ixx="0.000416666666667" ixy="0" ixz="0" iyy="0.000416666666667" iyz="0" izz="0.000416666666667"/>
    </inertial>
  </link>
  <link name="finger_upper_link_120">
    <visual>
      <origin rpy="0 0 0" xyz="0 0.0235 0"/>
      <geometry>
        <mesh filename="package://robot_properties_fingers/meshes/stl/pro/SIM__BL-Finger_Proximal.stl" scale="1.0 1.0 1.0"/>
      </geometry>
      <material name="real_finger_material"/>
    </visual>
    <collision>
      <origin rpy="0 0 0" xyz="0 0.0235 0"/>
      <geometry>
        <mesh filename="package://robot_properties_fingers/meshes/stl/pro/SIM__BL-Finger_Proximal.stl" scale="1.0 1.0 1.0"/>
      </geometry>
    </collision>
    <inertial>
      <origin rpy="0 0 0" xyz="0 0.06 0"/>
      <mass value="0.26"/>
      <inertia ixx="0.000459333333333" ixy="0" ixz="0" iyy="6.93333333333e-05" iyz="0" izz="0.000459333333333"/>
    </inertial>
  </link>
  <link name="finger_middle_link_120">
    <visual>
      <origin rpy="1.57079632679 0 0" xyz="0 0 0"/>
      <geometry>
        <mesh filename="package://robot_properties_fingers/meshes/stl/pro/SIM__BL-Finger_Intermediate.stl" scale="1.0 1.0 1.0"/>
      </geometry>
      <material name="real_finger_material"/>
    </visual>
    <collision>
      <origin rpy="1.57079632679 0 0" xyz="0 0 0"/>
      <geometry>
        <mesh filename="package://robot_properties_fingers/meshes/stl/pro/SIM__BL-Finger_Intermediate.stl" scale="1.0 1.0 1.0"/>
      </geometry>
    </collision>
    <inertial>
      <origin rpy="0 0 0" xyz="0.028 0 -0.08"/>
      <mass value="0.25"/>
      <inertia ixx="0.000441666666667" ixy="0" ixz="0" iyy="0.000441666666667" iyz="0" izz="6.66666666667e-05"/>
    </inertial>
  </link>
  <link name="finger_lower_link_120">
    <visual>
      <origin rpy="1.57079632679 0 0" xyz="0 0 0"/>
      <geometry>
        <mesh filename="package://robot_properties_fingers/meshes/stl/pro/SIM__BL-Finger_Tip_without_tip.stl" scale="1.0 1.0 1.0"/>
      </geometry>
      <material name="real_finger_material"/>
    </visual>
    <collision>
      <origin rpy="1.57079632679 0 0" xyz="0 0 0"/>
      <geometry>
        <mesh filename="package://robot_properties_fingers/meshes/stl/pro/SIM__BL-Finger_Tip_without_tip.stl" scale="1.0 1.0 1.0"/>
      </geometry>
    </collision>
    <inertial>
      <origin rpy="0 0 0" xyz="0 0 -0.06"/>
      <mass value="0.021"/>
      <inertia ixx="3.5e-05" ixy="0" ixz="0" iyy="3.5e-05" iyz="0" izz="1.4e-06"/>
    </inertial>
  </link>
  <!-- fixed link for finger tip -->
  <link name="finger_tip_link_120">
    <visual>
      <origin rpy="1.57079632679 0 0" xyz="-0.0185 0 0.1626"/>
      <geometry>
        <mesh filename="package://robot_properties_fingers/meshes/stl/pro/SIM__BL-Finger_Tip_actual_tip.stl" scale="1.0 1.0 1.0"/>
      </geometry>
      <material name="real_finger_material"/>
    </visual>
    <collision>
      <origin rpy="1.57079632679 0 0" xyz="-0.0185 0 0.1626"/>
      <geometry>
        <mesh filename="package://robot_properties_fingers/meshes/stl/pro/SIM__BL-Finger_Tip_actual_tip.stl" scale="1.0 1.0 1.0"/>
      </geometry>
    </collision>
    <inertial>
      <origin rpy="0 0 0" xyz="0 0 0"/>
      <mass value="0.031"/>
      <inertia ixx="5.16666666667e-07" ixy="0" ixz="0" iyy="5.16666666667e-07" iyz="0" izz="5.16666666667e-07"/>
    </inertial>
  </link>
  <joint name="finger_lower_to_tip_joint_120" type="fixed">
    <parent link="finger_lower_link_120"/>
    <child link="finger_tip_link_120"/>
    <origin xyz="0.0185 0 -0.1626"/>
  </joint>
  <!-- kinematics -->
  <!-- NOTE: Joint limits are set according to soft limits in the
             configuration of the real robot (i.e. not according to physical
             limits). -->
  <joint name="finger_base_to_upper_joint_120" type="revolute">
    <parent link="finger_base_link_120"/>
    <child link="finger_upper_link_120"/>
    <limit effort="1000" lower="-0.9" upper="1.4" velocity="1000"/>
    <axis xyz="0 1 0"/>
    <origin rpy="0 0 0" xyz="0 0 0"/>
  </joint>
  <joint name="finger_upper_to_middle_joint_120" type="revolute">
    <parent link="finger_upper_link_120"/>
    <child link="finger_middle_link_120"/>
    <limit effort="1000" lower="-1.57" upper="1.57" velocity="1000"/>
    <axis xyz="1 0 0"/>
    <origin rpy="0 0 0" xyz="0.01685 0.0505 0"/>
  </joint>
  <joint name="finger_middle_to_lower_joint_120" type="revolute">
    <parent link="finger_middle_link_120"/>
    <child link="finger_lower_link_120"/>
    <limit effort="1000" lower="-2.7" upper="0.0" velocity="1000"/>
    <axis xyz="1 0 0"/>
    <origin rpy="0 0 0" xyz="0.04922 0 -0.16"/>
  </joint>
  <!--
        Fixed links for the finger base (parts where the upper link is mounted).
        Note: Link Frames already coincide with the joint location
        -->
  <link name="finger_base_link_240">
    <visual>
      <origin rpy="0 0 0" xyz="0 0.23295 0"/>
      <geometry>
        <mesh filename="package://robot_properties_fingers/meshes/stl/pro/SIM__BL-Finger_Base.stl" scale="1.0 1.0 1.0"/>
      </geometry>
      <material name="real_finger_material"/>
    </visual>
    <collision>
      <origin rpy="0 0 0" xyz="0 0.23295 0"/>
      <geometry>
        <mesh filename="package://robot_properties_fingers/meshes/stl/pro/SIM__BL-Finger_Base.stl" scale="1.0 1.0 1.0"/>
      </geometry>
    </collision>
    <inertial>
      <origin rpy="0 0 0" xyz="0 0 0"/>
      <mass value="1"/>
      <inertia ixx="0.000416666666667" ixy="0" ixz="0" iyy="0.000416666666667" iyz="0" izz="0.000416666666667"/>
    </inertial>
  </link>
  <link name="finger_upper_link_240">
    <visual>
      <origin rpy="0 0 0" xyz="0 0.0235 0"/>
      <geometry>
        <mesh filename="package://robot_properties_fingers/meshes/stl/pro/SIM__BL-Finger_Proximal.stl" scale="1.0 1.0 1.0"/>
      </geometry>
      <material name="real_finger_material"/>
    </visual>
    <collision>
      <origin rpy="0 0 0" xyz="0 0.0235 0"/>
      <geometry>
        <mesh filename="package://robot_properties_fingers/meshes/stl/pro/SIM__BL-Finger_Proximal.stl" scale="1.0 1.0 1.0"/>
      </geometry>
    </collision>
    <inertial>
      <origin rpy="0 0 0" xyz="0 0.06 0"/>
      <mass value="0.26"/>
      <inertia ixx="0.000459333333333" ixy="0" ixz="0" iyy="6.93333333333e-05" iyz="0" izz="0.000459333333333"/>
    </inertial>
  </link>
  <link name="finger_middle_link_240">
    <visual>
      <origin rpy="1.57079632679 0 0" xyz="0 0 0"/>
      <geometry>
        <mesh filename="package://robot_properties_fingers/meshes/stl/pro/SIM__BL-Finger_Intermediate.stl" scale="1.0 1.0 1.0"/>
      </geometry>
      <material name="real_finger_material"/>
    </visual>
    <collision>
      <origin rpy="1.57079632679 0 0" xyz="0 0 0"/>
      <geometry>
        <mesh filename="package://robot_properties_fingers/meshes/stl/pro/SIM__BL-Finger_Intermediate.stl" scale="1.0 1.0 1.0"/>
      </geometry>
    </collision>
    <inertial>
      <origin rpy="0 0 0" xyz="0.028 0 -0.08"/>
      <mass value="0.25"/>
      <inertia ixx="0.000441666666667" ixy="0" ixz="0" iyy="0.000441666666667" iyz="0" izz="6.66666666667e-05"/>
    </inertial>
  </link>
  <link name="finger_lower_link_240">
    <visual>
      <origin rpy="1.57079632679 0 0" xyz="0 0 0"/>
      <geometry>
        <mesh filename="package://robot_properties_fingers/meshes/stl/pro/SIM__BL-Finger_Tip_without_tip.stl" scale="1.0 1.0 1.0"/>
      </geometry>
      <material name="real_finger_material"/>
    </visual>
    <collision>
      <origin rpy="1.57079632679 0 0" xyz="0 0 0"/>
      <geometry>
        <mesh filename="package://robot_properties_fingers/meshes/stl/pro/SIM__BL-Finger_Tip_without_tip.stl" scale="1.0 1.0 1.0"/>
      </geometry>
    </collision>
    <inertial>
      <origin rpy="0 0 0" xyz="0 0 -0.06"/>
      <mass value="0.021"/>
      <inertia ixx="3.5e-05" ixy="0" ixz="0" iyy="3.5e-05" iyz="0" izz="1.4e-06"/>
    </inertial>
  </link>
  <!-- fixed link for finger tip -->
  <link name="finger_tip_link_240">
    <visual>
      <origin rpy="1.57079632679 0 0" xyz="-0.0185 0 0.1626"/>
      <geometry>
        <mesh filename="package://robot_properties_fingers/meshes/stl/pro/SIM__BL-Finger_Tip_actual_tip.stl" scale="1.0 1.0 1.0"/>
      </geometry>
      <material name="real_finger_material"/>
    </visual>
    <collision>
      <origin rpy="1.57079632679 0 0" xyz="-0.0185 0 0.1626"/>
      <geometry>
        <mesh filename="package://robot_properties_fingers/meshes/stl/pro/SIM__BL-Finger_Tip_actual_tip.stl" scale="1.0 1.0 1.0"/>
      </geometry>
    </collision>
    <inertial>
      <origin rpy="0 0 0" xyz="0 0 0"/>
      <mass value="0.031"/>
      <inertia ixx="5.16666666667e-07" ixy="0" ixz="0" iyy="5.16666666667e-07" iyz="0" izz="5.16666666667e-07"/>
    </inertial>
  </link>
  <joint name="finger_lower_to_tip_joint_240" type="fixed">
    <parent link="finger_lower_link_240"/>
    <child link="finger_tip_link_240"/>
    <origin xyz="0.0185 0 -0.1626"/>
  </joint>
  <!-- kinematics -->
  <!-- NOTE: Joint limits are set according to soft limits in the
             configuration of the real robot (i.e. not according to physical
             limits). -->
  <joint name="finger_base_to_upper_joint_240" type="revolute">
    <parent link="finger_base_link_240"/>
    <child link="finger_upper_link_240"/>
    <limit effort="1000" lower="-0.9" upper="1.4" velocity="1000"/>
    <axis xyz="0 1 0"/>
    <origin rpy="0 0 0" xyz="0 0 0"/>
  </joint>
  <joint name="finger_upper_to_middle_joint_240" type="revolute">
    <parent link="finger_upper_link_240"/>
    <child link="finger_middle_link_240"/>
    <limit effort="1000" lower="-1.57" upper="1.57" velocity="1000"/>
    <axis xyz="1 0 0"/>
    <origin rpy="0 0 0" xyz="0.01685 0.0505 0"/>
  </joint>
  <joint name="finger_middle_to_lower_joint_240" type="revolute">
    <parent link="finger_middle_link_240"/>
    <child link="finger_lower_link_240"/>
    <limit effort="1000" lower="-2.7" upper="0.0" velocity="1000"/>
    <axis xyz="1 0 0"/>
    <origin rpy="0 0 0" xyz="0.04922 0 -0.16"/>
  </joint>
  <joint name="holder_to_finger_0" type="fixed">
    <parent link="upper_holder_link"/>
    <child link="finger_base_link_0"/>
    <origin rpy="0 0 0.0" xyz="0 0 0"/>
  </joint>
  <joint name="holder_to_finger_120" type="fixed">
    <parent link="upper_holder_link"/>
    <child link="finger_base_link_120"/>
    <origin rpy="0 0 -2.09439510239" xyz="0 0 0"/>
  </joint>
  <joint name="holder_to_finger_240" type="fixed">
    <parent link="upper_holder_link"/>
    <child link="finger_base_link_240"/>
    <origin rpy="0 0 -4.18879020479" xyz="0 0 0"/>
  </joint>
  <material name="table_material">
    <color rgba="0.31 0.27 0.25 1.0"/>
  </material>
  <material name="boundary_material">
    <color rgba="0.95 0.95 0.95 1.0"/>
  </material>
  <link name="table_link">
    <visual>
      <origin rpy="0 0 0" xyz="0 0 0"/>
      <geometry>
        <mesh filename="package://robot_properties_fingers/meshes/stl/trifinger_table_without_border.stl" scale="1 1 1"/>
      </geometry>
      <material name="table_material"/>
    </visual>
    <collision>
      <origin rpy="0 0 0" xyz="0 0 0"/>
      <geometry>
        <mesh filename="package://robot_properties_fingers/meshes/stl/trifinger_table_without_border.stl" scale="1 1 1"/>
      </geometry>
    </collision>
    <inertial>
      <origin rpy="0 0 0" xyz="0 0 0"/>
      <mass value="2"/>
      <inertia ixx="0.0962833333333" ixy="0" ixz="0" iyy="0.0840333333333" iyz="0" izz="0.180283333333"/>
    </inertial>
  </link>
  <link name="boundary_link">
    <visual>
      <origin rpy="0 0 0" xyz="0 0 0"/>
      <geometry>
        <mesh filename="package://robot_properties_fingers/meshes/stl/high_table_boundary.stl" scale="1 1 1"/>
      </geometry>
      <material name="boundary_material"/>
    </visual>
    <collision>
      <origin rpy="0 0 0" xyz="0 0 0"/>
      <geometry>
        <mesh filename="package://robot_properties_fingers/meshes/stl/high_table_boundary.stl" scale="1 1 1"/>
      </geometry>
    </collision>
    <inertial>
      <origin rpy="0 0 0" xyz="0 0 0"/>
      <mass value="2"/>
      <inertia ixx="0.0570833333333" ixy="0" ixz="0" iyy="0.0570833333333" iyz="0" izz="0.104533333333"/>
    </inertial>
  </link>
  <joint name="base_to_table" type="fixed">
    <parent link="base_link"/>
    <child link="table_link"/>
    <origin xyz="0 0 0"/>
  </joint>
  <joint name="table_to_boundary" type="fixed">
    <parent link="table_link"/>
    <child link="boundary_link"/>
    <origin xyz="0 0 0"/>
  </joint>
</robot>
